Workbook

Sheet Read Me
A1: UK Oil Plc — Rights Issue & Finance Options Model
A2: 6012LBSBW International Corporate Finance (LJMU) · 2026 Assessment Brief (Sem 1 v1) · Week 3: Sources of Finance
A5: What it does
B6: Compares every way of financing the two options in the brief — equity, debt or a combination — on cost, gearing and risk. Also prices a rights issue to fund Option 1 (North Sea platform) and Option 2 (acquiring 80% or 100% of Arabic Oil Supplies), using the brief's numbers and the Week 3 method.
A8: How to use it
A9: 1 | B9: Change only the YELLOW cells on Inputs: issue price, platform supplier, EUR/GBP rate, % funded by equity, example shareholder stake.
A10: 2 | B10: Read the answers on Rights Issue, Balance Sheet and Dilution — three scenarios side by side.
A11: 3 | B11: Use Price Sensitivity to compare issue prices across the bank's £1.00–£1.25 range (pick the scenario in its yellow cell).
A12: 4 | B12: Finance Options compares 100% equity, four types of 100% debt and a combination: fees, cost, gearing, interest cover and risks, plus a gearing ladder (Week 3 slides 52–62).
A13: 5 | B13: Week 3 Example rebuilds the lecture's 1-for-5 example with the same formulas — every line matches the slide answers.
A15: Colour key
A16: Example 1.25 | B16: Blue text = a number typed in from the brief or the slides.
A17: Example 1.25 | B17: Black text = a formula calculated in this tab.
A18: Example 1.25 | B18: Green text = a figure pulled from another tab.
A19: Example 1.25 | B19: Yellow fill = an assumption or choice you should check and change.
A21: Formulas used
A22: Value of the right | B22: Market price − issue price (Week 3 slide 28 — the module's definition).
A23: TERP | B23: (N × cum-rights price + issue price) ÷ (N + 1), N = existing shares per new share (slide 34).
A24: Nil-paid right | B24: TERP − issue price (the textbook value, shown as a cross-check).
A25: Share premium | B25: (Issue price − nominal value) × new shares (slide 28), less issue costs (Companies Act 2006 s.610(2)).
A26: Book value per share | B26: Ordinary shareholders' funds ÷ ordinary shares (slide 29). Preference shares excluded.
A27: Shares to issue | B27: (Net cash needed + £5M fees) ÷ issue price — the fees have to be raised too.
A29: Watch-outs
A30: Bank Rate | B30: 3.75% (held 17 Sep 2026; next decision 5 Nov 2026, markets expect a rise). Re-check on bankofengland.co.uk before you submit.
A31: Bond coupon | B31: 6% is an ESTIMATE for a BBB+ issuer (sterling IG index yield 5.71%, Aug 2026). Replace it with a live BBB yield.
A32: Tax rate | B32: 25% (UK main rate, as in the NPV workings). Oil ring-fence profits are taxed more heavily — confirm the rate.
A33: EUR/GBP | B33: 0.85 is a PLACEHOLDER. Replace it with the real-time rate and cite the source — 10% of marks are for real-time information.
A34: Threshold | B34: The 2026 brief says the value of the right must be over £1.00 (Week 3 slides said £1.50 for an older version of the case).
A35: TERP | B35: TERP is theoretical. Slide 34: the real price depends on whether the market believes the investment will work.
A36: Debt mix | B36: If you set equity below 100%, the rest is shown as new debt, but loan/bond fees aren't modelled here.
A37: Report | B37: Don't list equity vs debt pros and cons — Week 3 says that scores zero. Use these numbers to justify ONE recommendation.
A38: AI use | B38: The brief is Tier Two: if you use GenAI, your report/slides must include an AI acknowledgement (tool, provider, URL, how used, free/paid).

Sheet Inputs
A1: UK Oil Plc — Rights Issue Model: Inputs
A2: Every number from the 2026 Assessment Brief lives here. Change ONLY the yellow cells; every other tab recalculates.
A4: Input | B4: Value | C4: Unit | D4: Source / note
A5: UK Oil Plc — current capital structure (Assessment Brief: Company Background)
A6: £1 Ordinary share capital | B6: 1000 | C6: £M | D6: Brief: '£1 Ordinary Shares 1000' (£M).
A7: Nominal (face) value per ordinary share | B7: 1 | C7: £ | D7: Brief: '£1 Ordinary Shares'.
A8: Ordinary shares in issue | B8: =B6/B7 -> 1000 | C8: M shares | D8: Share capital ÷ nominal value = 1,000M shares.
A9: Current market price per ordinary share (cum-rights) | B9: 3.5 | C9: £ | D9: Brief: 'Current Market Price Per Ordinary Share: £3.50'.
A10: £1 6% Preference shares | B10: 225 | C10: £M | D10: Brief.
A11: Retained profits | B11: 700 | C11: £M | D11: Brief. Remember (Week 3): retained profit is NOT cash.
A12: Total equity | B12: =B6+B10+B11 -> 1925 | C12: £M | D12: Brief total: £1,925M.
A13: Unsecured 6% Bond 2027 | B13: 500 | C13: £M | D13: Brief says 2027 (Week 3 slides said 2025 — the brief is the official document).
A14: Secured loan (floating rate 7%) | B14: 200 | C14: £M | D14: Brief.
A15: Total debt | B15: =B13+B14 -> 700 | C15: £M | D15: Brief total: £700M.
A16: Capital employed (equity + debt) | B16: =B12+B15 -> 2625 | C16: £M | D16: Brief total: £2,625M.
A17: Rights issue terms (Assessment Brief: Financing the Project → Equity Finance)
A18: Issue price — BASE CASE (change me) | B18: 1.25 | C18: £ | D18: Your choice inside the bank's range. £1.25 = top of range → fewest new shares, least dilution. Try £1.00, or use the Price Sensitivity tab.
A19: Bank's suggested issue price — low | B19: 1 | C19: £ | D19: Brief: 'a share price in the region of £1 to £1.25 would result in a successful issue'.
A20: Bank's suggested issue price — high | B20: 1.25 | C20: £ | D20: Brief (as above).
A21: Underwriting / issue fees (fixed, regardless of size) | B21: 5 | C21: £M | D21: Brief: '£5 million, regardless of the size of the issue'.
A22: Value of the right must be OVER | B22: 1 | C22: £ | D22: Brief, Option 2: 'a Rights Issue would attract support provided the value of the right is over £1.00'. Week 3 slides said £1.50 for an older 'Euro Refinery' version of the case — use the 2026 brief.
A23: Option 1 — North Sea reservoir: what needs funding
A24: Platform supplier chosen (British / Munchen) | B24: British | C24: text | D24: Activity J. Pick the supplier you recommend from the drop-down.
A25: British Oil Machinery quote | B25: 300 | C25: £M | D25: Brief, Activity J.
A26: Munchen Machinery Germany quote | B26: 355 | C26: €M | D26: Brief, Activity J.
A27: Exchange rate: £ per €1 | B27: 0.85 | C27: £/€ | D27: PLACEHOLDER — replace with today's EUR/GBP rate from the Bank of England and cite it (brief requires real-time rates).
A28: Munchen quote converted to £ | B28: =B26*B27 -> 301.75 | C28: £M | D28: € quote × £ per €.
A29: Platform cost used | B29: =IF(B24="Munchen",B28,B25) -> 300 | C29: £M | D29: Follows the supplier choice above.
A30: Activity E: finalise bid & pay bonds | B30: 10 | C30: £M | D30: Brief: '£10 million'. The £20M geological study (Activity A) is sunk — excluded.
A31: Total Option 1 funding need | B31: =B29+B30 -> 310 | C31: £M | D31: Platform + bid costs.
A32: Share of Option 1 funded by the rights issue | B32: 1 | C32: % | D32: 100% = all-equity. Set e.g. 50% for a combination; the rest shows as new debt on the Balance Sheet tab (debt fees not modelled here).
A33: Option 2 — Acquisition of Arabic Oil Supplies (AOS)
A34: AOS ordinary shares in issue | B34: 250 | C34: M shares | D34: Brief: AOS share capital $250,000k of $1 shares = 250M shares.
A35: Offer price per AOS share | B35: 1.3 | C35: £ | D35: Brief: 'An Acquisition of 80 – 100% ... at £1.30 per share'.
A36: Stake acquired — low case | B36: 0.8 | C36: % | D36: Brief: 80%.
A37: Stake acquired — high case | B37: 1 | C37: % | D37: Brief: 100%.
A38: Acquisition cost — 80% stake | B38: =B34*B35*B36 -> 260 | C38: £M | D38: Shares × price × stake.
A39: Acquisition cost — 100% stake | B39: =B34*B35*B37 -> 325 | C39: £M | D39: Shares × price × stake.
A40: Share of Option 2 funded by the rights issue | B40: 1 | C40: % | D40: Brief: financed by 'either a Rights Issue or Debt'.
A41: Debt finance (Assessment Brief: Bank Loan & Bonds) + real-time rates
...

Sheet Rights Issue
A1: Rights Issue — three funding scenarios
A2: £M unless stated. Base-case issue price and funding mix come from the yellow cells on Inputs.
A4: Item | B4: Unit | C4: Option 1: North Sea | D4: Option 2: Acquire 80% | E4: Option 2: Acquire 100% | F4: What it means
A6: A. How much do we need to raise?
A7: Total funding need | B7: £M | C7: =Inputs!$B$31 -> 310 | D7: =Inputs!$B$38 -> 260 | E7: =Inputs!$B$39 -> 325 | F7: Option 1 = platform + £10M bid costs. Option 2 = AOS shares × stake × £1.30.
A8: Share funded by the rights issue | B8: % | C8: =Inputs!$B$32 -> 1 | D8: =Inputs!$B$40 -> 1 | E8: =Inputs!$B$40 -> 1 | F8: Change on Inputs to model a debt/equity combination.
A9: Net cash needed from the rights issue | B9: £M | C9: =C7*C8 -> 310 | D9: =D7*D8 -> 260 | E9: =E7*E8 -> 325 | F9: The money that actually has to reach the company.
A10: Add: underwriting / issue fees | B10: £M | C10: =IF(C9>0,Inputs!$B$21,0) -> 5 | D10: =IF(D9>0,Inputs!$B$21,0) -> 5 | E10: =IF(E9>0,Inputs!$B$21,0) -> 5 | F10: Fixed £5M whatever the size — so you must raise MORE than you need.
A11: Gross amount to raise | B11: £M | C11: =C9+C10 -> 315 | D11: =D9+D10 -> 265 | E11: =E9+E10 -> 330 | F11: Net need + fees.
A12: Issue price | B12: £ | C12: =Inputs!$B$18 -> 1.25 | D12: =Inputs!$B$18 -> 1.25 | E12: =Inputs!$B$18 -> 1.25 | F12: Base case from Inputs.
A13: New shares to issue | B13: M shares | C13: =IF(C12>0,C11/C12,0) -> 252 | D13: =IF(D12>0,D11/D12,0) -> 212 | E13: =IF(E12>0,E11/E12,0) -> 264 | F13: Gross amount ÷ issue price.
A15: B. Rights terms — '1 new share for every N held'
A16: Existing ordinary shares | B16: M shares | C16: =Inputs!$B$8 -> 1000 | D16: =Inputs!$B$8 -> 1000 | E16: =Inputs!$B$8 -> 1000
A17: N — existing shares needed to buy one new share | B17: x | C17: =IF(C13>0,C16/C13,0) -> 3.968254 | D17: =IF(D13>0,D16/D13,0) -> 4.7169811 | E17: =IF(E13>0,E16/E13,0) -> 3.7878788 | F17: Week 3 slide 34: N = number of shares required to buy one new share.
A18: Rights terms (exact) | B18: text | C18: =IF(C13>0,"1 for "&TEXT(C17,"0.00"),"No issue") -> 1 for 3.97 | D18: =IF(D13>0,"1 for "&TEXT(D17,"0.00"),"No issue") -> 1 for 4.72 | E18: =IF(E13>0,"1 for "&TEXT(E17,"0.00"),"No issue") -> 1 for 3.79 | F18: Real issues use whole-number ratios — see section C.
A19: Total shares after the issue | B19: M shares | C19: =C16+C13 -> 1252 | D19: =D16+D13 -> 1212 | E19: =E16+E13 -> 1264
A20: New shares as % of enlarged share capital | B20: % | C20: =IF(C19>0,C13/C19,0) -> 0.20127796 | D20: =IF(D19>0,D13/D19,0) -> 0.17491749 | E20: =IF(E19>0,E13/E19,0) -> 0.20886076
A22: C. Practical whole-number terms (what you'd actually announce)
A23: Nearest whole-number N | B23: x | C23: =IF(C13>0,MAX(1,ROUND(C17,0)),0) -> 4 | D23: =IF(D13>0,MAX(1,ROUND(D17,0)),0) -> 5 | E23: =IF(E13>0,MAX(1,ROUND(E17,0)),0) -> 4
A24: Announced terms | B24: text | C24: =IF(C23>0,"1 for "&C23,"No issue") -> 1 for 4 | D24: =IF(D23>0,"1 for "&D23,"No issue") -> 1 for 5 | E24: =IF(E23>0,"1 for "&E23,"No issue") -> 1 for 4
A25: New shares under these terms | B25: M shares | C25: =IF(C23>0,C16/C23,0) -> 250 | D25: =IF(D23>0,D16/D23,0) -> 200 | E25: =IF(E23>0,E16/E23,0) -> 250
A26: Gross cash at the base-case price | B26: £M | C26: =C25*C12 -> 312.5 | D26: =D25*D12 -> 250 | E26: =E25*E12 -> 312.5
A27: Surplus / (shortfall) vs gross amount needed | B27: £M | C27: =C26-C11 -> -2.5 | D27: =D26-D11 -> -15 | E27: =E26-E11 -> -17.5 | F27: Negative = this whole-number ratio doesn't quite raise enough at the base-case price.
A28: Issue price that makes these terms raise exactly enough | B28: £ | C28: =IF(C25>0,C11/C25,0) -> 1.26 | D28: =IF(D25>0,D11/D25,0) -> 1.325 | E28: =IF(E25>0,E11/E25,0) -> 1.32 | F28: Compare with the bank's £1.00–£1.25 range.
A29: Is that price inside the bank's range? | B29: check | C29: =IF(AND(C28>=Inputs!$B$19,C28<=Inputs!$B$20),"Yes","No") -> No | D29: =IF(AND(D28>=Inputs!$B$19,D28<=Inputs!$B$20),"Yes","No") -> No | E29: =IF(AND(E28>=Inputs!$B$19,E28<=Inputs!$B$20),"Yes","No") -> No
A31: D. Cash received & how it's recorded
A32: Gross cash received | B32: £M | C32: =C13*C12 -> 315 | D32: =D13*D12 -> 265 | E32: =E13*E12 -> 330 | F32: Week 3 slide 28: new shares × issue price.
A33: Less: issue fees | B33: £M | C33: =-C10 -> -5 | D33: =-D10 -> -5 | E33: =-E10 -> -5
A34: Net cash received | B34: £M | C34: =C32+C33 -> 310 | D34: =D32+D33 -> 260 | E34: =E32+E33 -> 325
A35: Check: net cash = net need | B35: check | C35: =IF(ABS(C34-C9)<0.0001,"OK","CHECK") -> OK | D35: =IF(ABS(D34-D9)<0.0001,"OK","CHECK") -> OK | E35: =IF(ABS(E34-E9)<0.0001,"OK","CHECK") -> OK
A36: Increase in £1 ordinary share capital (nominal) | B36: £M | C36: =C13*Inputs!$B$7 -> 252 | D36: =D13*Inputs!$B$7 -> 212 | E36: =E13*Inputs!$B$7 -> 264 | F36: Each new share adds its £1 face value to share capital.
A37: Share premium — gross | B37: £M | C37: =C13*(C12-Inputs!$B$7) -> 63 | D37: =D13*(D12-Inputs!$B$7) -> 53 | E37: =E13*(E12-Inputs!$B$7) -> 66 | F37: Week 3 slide 28: (issue price − nominal value) × new shares.
A38: Less: issue costs written off to share premium | B38: £M | C38: =-C10 -> -5 | D38: =-D10 -> -5 | E38: =-E10 -> -5 | F38: Companies Act 2006 s.610(2) lets issue expenses be written off against share premium.
A39: Share premium — net | B39: £M | C39: =C37+C38 -> 58 | D39: =D37+D38 -> 48 | E39: =E37+E38 -> 61
A40: Issue costs as % of gross proceeds | B40: % | C40: =IF(C32>0,C10/C32,0) -> 0.015873016 | D40: =IF(D32>0,D10/D32,0) -> 0.018867925 | E40: =IF(E32>0,E10/E32,0) -> 0.015151515 | F40: Use when comparing the COST of equity vs debt finance (debt fees: £3M–£4M loan, £10M bond).
A42: E. Value of the right & share price after the issue
A43: Market price per share (cum-rights) | B43: £ | C43: =Inputs!$B$9 -> 3.5 | D43: =Inputs!$B$9 -> 3.5 | E43: =Inputs!$B$9 -> 3.5
A44: Discount of issue price to market price | B44: % | C44: =IF(C43>0,1-C12/C43,0) -> 0.64285714 | D44: =IF(D43>0,1-D12/D43,0) -> 0.64285714 | E44: =IF(E43>0,1-E12/E43,0) -> 0.64285714 | F44: Deep discount = very likely to succeed, but more new shares needed.
A45: Value of the right — LECTURE definition (market − issue) | B45: £ | C45: =C43-C12 -> 2.25 | D45: =D43-D12 -> 2.25 | E45: =E43-E12 -> 2.25 | F45: Week 3 slide 28: £2.50 − £2.00 = £0.50. This is the module's definition.
A46: TERP: (N × cum-rights price + issue price) ÷ (N + 1) | B46: £ | C46: =IF(C13>0,(C17*C43+C12)/(C17+1),C43) -> 3.0471246 | D46: =IF(D13>0,(D17*D43+D12)/(D17+1),D43) -> 3.1064356 | E46: =IF(E13>0,(E17*E43+E12)/(E17+1),E43) -> 3.0300633 | F46: Week 3 slide 34. The theoretical share price once the shares trade ex-rights.
...

Sheet Finance Options
A1: Finance Options — Equity, Debt or a Combination? (Week 3 slides 52–62)
A2: Same funding need, six ways to raise it. £M unless stated. Change the option, debt type and mix in the yellow cells on Inputs.
A4: Item | B4: Unit | C4: 100% Equity: rights issue | D4: 100% Debt: floating loan | E4: 100% Debt: fixed loan | F4: 100% Debt: currency loan | G4: 100% Debt: bond | H4: Combination | I4: What it means
A6: A. Raising the money
A7: Funding need for the selected option | B7: £M | C7: =INDEX('Rights Issue'!$C$7:$E$7,1,Inputs!$B$62) -> 310 | D7: =INDEX('Rights Issue'!$C$7:$E$7,1,Inputs!$B$62) -> 310 | E7: =INDEX('Rights Issue'!$C$7:$E$7,1,Inputs!$B$62) -> 310 | F7: =INDEX('Rights Issue'!$C$7:$E$7,1,Inputs!$B$62) -> 310 | G7: =INDEX('Rights Issue'!$C$7:$E$7,1,Inputs!$B$62) -> 310 | H7: =INDEX('Rights Issue'!$C$7:$E$7,1,Inputs!$B$62) -> 310 | I7: Option picked on Inputs (1 = North Sea, 2 = AOS 80%, 3 = AOS 100%).
A8: Share raised as equity | B8: % | C8: 1 | D8: 0 | E8: 0 | F8: 0 | G8: 0 | H8: =Inputs!$B$64 -> 0.5
A9: Equity raised (net) | B9: £M | C9: =C7*C8 -> 310 | D9: =D7*D8 -> 0 | E9: =E7*E8 -> 0 | F9: =F7*F8 -> 0 | G9: =G7*G8 -> 0 | H9: =H7*H8 -> 155
A10: Debt raised (net) | B10: £M | C10: =C7-C9 -> 0 | D10: =D7-D9 -> 310 | E10: =E7-E9 -> 310 | F10: =F7-F9 -> 310 | G10: =G7-G9 -> 310 | H10: =H7-H9 -> 155
A11: Equity issue fees | B11: £M | C11: =IF(C9>0,Inputs!$B$21,0) -> 5 | D11: =IF(D9>0,Inputs!$B$21,0) -> 0 | E11: =IF(E9>0,Inputs!$B$21,0) -> 0 | F11: =IF(F9>0,Inputs!$B$21,0) -> 0 | G11: =IF(G9>0,Inputs!$B$21,0) -> 0 | H11: =IF(H9>0,Inputs!$B$21,0) -> 5 | I11: £5M underwriting, whatever the size.
A12: Debt fees | B12: £M | C12: 0 | D12: =IF(D10>0,Inputs!$B$56,0) -> 3 | E12: =IF(E10>0,Inputs!$B$57,0) -> 4 | F12: =IF(F10>0,Inputs!$B$58,0) -> 3.25 | G12: =IF(G10>0,Inputs!$B$59,0) -> 10 | H12: =IF(H10>0,Inputs!$B$66,0) -> 3 | I12: Loan £3M (+£1M to fix) · currency loan £3.25M · bond £10M.
A13: Total upfront fees | B13: £M | C13: =C11+C12 -> 5 | D13: =D11+D12 -> 3 | E13: =E11+E12 -> 4 | F13: =F11+F12 -> 3.25 | G13: =G11+G12 -> 10 | H13: =H11+H12 -> 8 | I13: A combination pays BOTH sets of fixed fees.
A14: Gross equity to raise (incl. fees) | B14: £M | C14: =IF(C9>0,C9+C11,0) -> 315 | D14: =IF(D9>0,D9+D11,0) -> 0 | E14: =IF(E9>0,E9+E11,0) -> 0 | F14: =IF(F9>0,F9+F11,0) -> 0 | G14: =IF(G9>0,G9+G11,0) -> 0 | H14: =IF(H9>0,H9+H11,0) -> 160
A15: Gross debt to borrow (incl. fees) | B15: £M | C15: =IF(C10>0,C10+C12,0) -> 0 | D15: =IF(D10>0,D10+D12,0) -> 313 | E15: =IF(E10>0,E10+E12,0) -> 314 | F15: =IF(F10>0,F10+F12,0) -> 313.25 | G15: =IF(G10>0,G10+G12,0) -> 320 | H15: =IF(H10>0,H10+H12,0) -> 158 | I15: Fees are borrowed too.
A16: New shares issued at the base-case price | B16: M shares | C16: =IF(Inputs!$B$18>0,C14/Inputs!$B$18,0) -> 252 | D16: =IF(Inputs!$B$18>0,D14/Inputs!$B$18,0) -> 0 | E16: =IF(Inputs!$B$18>0,E14/Inputs!$B$18,0) -> 0 | F16: =IF(Inputs!$B$18>0,F14/Inputs!$B$18,0) -> 0 | G16: =IF(Inputs!$B$18>0,G14/Inputs!$B$18,0) -> 0 | H16: =IF(Inputs!$B$18>0,H14/Inputs!$B$18,0) -> 128
A17: Fees as % of money raised | B17: % | C17: =IF((C14+C15)>0,C13/(C14+C15),0) -> 0.015873016 | D17: =IF((D14+D15)>0,D13/(D14+D15),0) -> 0.0095846645 | E17: =IF((E14+E15)>0,E13/(E14+E15),0) -> 0.012738854 | F17: =IF((F14+F15)>0,F13/(F14+F15),0) -> 0.0103751 | G17: =IF((G14+G15)>0,G13/(G14+G15),0) -> 0.03125 | H17: =IF((H14+H15)>0,H13/(H14+H15),0) -> 0.025157233
A19: B. Cost of finance — which is cheaper, equity or debt? (slide 53)
A20: Cost of equity Ke (dividend growth model) | B20: % | C20: =IF(C9>0,Inputs!$B$74,0) -> 0.16135011 | D20: =IF(D9>0,Inputs!$B$74,0) -> 0 | E20: =IF(E9>0,Inputs!$B$74,0) -> 0 | F20: =IF(F9>0,Inputs!$B$74,0) -> 0 | G20: =IF(G9>0,Inputs!$B$74,0) -> 0 | H20: =IF(H9>0,Inputs!$B$74,0) -> 0.16135011 | I20: What shareholders expect: D1 ÷ P0 + g.
A21: Pre-tax interest rate on the new debt | B21: % | C21: 0 | D21: =IF(D10>0,Inputs!$B$47,0) -> 0.0575 | E21: =IF(E10>0,Inputs!$B$48,0) -> 0.07 | F21: =IF(F10>0,Inputs!$B$49,0) -> 0.0575 | G21: =IF(G10>0,Inputs!$B$50,0) -> 0.06 | H21: =IF(H10>0,Inputs!$B$65,0) -> 0.0575 | I21: Floating = Bank Rate 3.75% + 2%. Fixed = 7% for 5 years only.
A22: After-tax cost of debt Kd × (1 − t) | B22: % | C22: =C21*(1-Inputs!$B$82) -> 0 | D22: =D21*(1-Inputs!$B$82) -> 0.043125 | E22: =E21*(1-Inputs!$B$82) -> 0.0525 | F22: =F21*(1-Inputs!$B$82) -> 0.043125 | G22: =G21*(1-Inputs!$B$82) -> 0.045 | H22: =H21*(1-Inputs!$B$82) -> 0.043125 | I22: Interest is tax-deductible; dividends are not.
A23: Weighted cost of the new money | B23: % | C23: =C8*C20+(1-C8)*C22 -> 0.16135011 | D23: =D8*D20+(1-D8)*D22 -> 0.043125 | E23: =E8*E20+(1-E8)*E22 -> 0.0525 | F23: =F8*F20+(1-F8)*F22 -> 0.043125 | G23: =G8*G20+(1-G8)*G22 -> 0.045 | H23: =H8*H20+(1-H8)*H22 -> 0.10223756 | I23: Lower = cheaper. Ignores the extra return shareholders demand as gearing rises.
A24: Year-1 dividends on the new shares | B24: £M | C24: =C16*Inputs!$B$73 -> 18.676073 | D24: =D16*Inputs!$B$73 -> 0 | E24: =E16*Inputs!$B$73 -> 0 | F24: =F16*Inputs!$B$73 -> 0 | G24: =G16*Inputs!$B$73 -> 0 | H24: =H16*Inputs!$B$73 -> 9.4862595 | I24: And growing at g a year — shares are permanent (slide 59).
A25: Year-1 interest on the new debt | B25: £M | C25: =C15*C21 -> 0 | D25: =D15*D21 -> 17.9975 | E25: =E15*E21 -> 21.98 | F25: =F15*F21 -> 18.011875 | G25: =G15*G21 -> 19.2 | H25: =H15*H21 -> 9.085
A26: Less: tax relief on interest | B26: £M | C26: =-C25*Inputs!$B$82 -> 0 | D26: =-D25*Inputs!$B$82 -> -4.499375 | E26: =-E25*Inputs!$B$82 -> -5.495 | F26: =-F25*Inputs!$B$82 -> -4.5029687 | G26: =-G25*Inputs!$B$82 -> -4.8 | H26: =-H25*Inputs!$B$82 -> -2.27125
A27: Year-1 cash cost after tax | B27: £M | C27: =C24+C25+C26 -> 18.676073 | D27: =D24+D25+D26 -> 13.498125 | E27: =E24+E25+E26 -> 16.485 | F27: =F24+F25+F26 -> 13.508906 | G27: =G24+G25+G26 -> 14.4 | H27: =H24+H25+H26 -> 16.30001
A29: C. Level of gearing / leverage (slides 60–61)
A30: Total equity after | B30: £M | C30: =Inputs!$B$12+C9 -> 2235 | D30: =Inputs!$B$12+D9 -> 1925 | E30: =Inputs!$B$12+E9 -> 1925 | F30: =Inputs!$B$12+F9 -> 1925 | G30: =Inputs!$B$12+G9 -> 1925 | H30: =Inputs!$B$12+H9 -> 2080 | I30: Today £1,925M. Equity fees are written off to share premium.
A31: Total debt after | B31: £M | C31: =Inputs!$B$15+C15 -> 700 | D31: =Inputs!$B$15+D15 -> 1013 | E31: =Inputs!$B$15+E15 -> 1014 | F31: =Inputs!$B$15+F15 -> 1013.25 | G31: =Inputs!$B$15+G15 -> 1020 | H31: =Inputs!$B$15+H15 -> 858 | I31: Today £700M.
A32: Gearing — debt ÷ equity | B32: % | C32: =IF(C30>0,C31/C30,0) -> 0.31319911 | D32: =IF(D30>0,D31/D30,0) -> 0.52623377 | E32: =IF(E30>0,E31/E30,0) -> 0.52675325 | F32: =IF(F30>0,F31/F30,0) -> 0.52636364 | G32: =IF(G30>0,G31/G30,0) -> 0.52987013 | H32: =IF(H30>0,H31/H30,0) -> 0.4125 | I32: Today 36.4%.
A33: Gearing — debt ÷ (debt + equity) | B33: % | C33: =IF((C30+C31)>0,C31/(C30+C31),0) -> 0.23850085 | D33: =IF((D30+D31)>0,D31/(D30+D31),0) -> 0.34479238 | E33: =IF((E30+E31)>0,E31/(E30+E31),0) -> 0.34501531 | F33: =IF((F30+F31)>0,F31/(F30+F31),0) -> 0.34484812 | G33: =IF((G30+G31)>0,G31/(G30+G31),0) -> 0.34634975 | H33: =IF((H30+H31)>0,H31/(H30+H31),0) -> 0.2920354 | I33: Today 26.7%.
A34: Change in debt ÷ equity vs today | B34: % | C34: =C32-Inputs!$B$15/Inputs!$B$12 -> -0.050437258 | D34: =D32-Inputs!$B$15/Inputs!$B$12 -> 0.1625974 | E34: =E32-Inputs!$B$15/Inputs!$B$12 -> 0.16311688 | F34: =F32-Inputs!$B$15/Inputs!$B$12 -> 0.16272727 | G34: =G32-Inputs!$B$15/Inputs!$B$12 -> 0.16623377 | H34: =H32-Inputs!$B$15/Inputs!$B$12 -> 0.048863636
A36: D. Burden of debt — high gearing will cost more (slide 62)
A37: Interest on existing debt at today's Bank Rate | B37: £M | C37: =Inputs!$B$81 -> 41 | D37: =Inputs!$B$81 -> 41 | E37: =Inputs!$B$81 -> 41 | F37: =Inputs!$B$81 -> 41 | G37: =Inputs!$B$81 -> 41 | H37: =Inputs!$B$81 -> 41 | I37: £500M bond at 6% + £200M loan at 5.50%.
A38: Total annual interest after | B38: £M | C38: =C37+C25 -> 41 | D38: =D37+D25 -> 58.9975 | E38: =E37+E25 -> 62.98 | F38: =F37+F25 -> 59.011875 | G38: =G37+G25 -> 60.2 | H38: =H37+H25 -> 50.085
A39: Profit before interest & tax (last year) | B39: £M | C39: =Inputs!$B$80 -> 544 | D39: =Inputs!$B$80 -> 544 | E39: =Inputs!$B$80 -> 544 | F39: =Inputs!$B$80 -> 544 | G39: =Inputs!$B$80 -> 544 | H39: =Inputs!$B$80 -> 544 | I39: £500M PBT + £44M interest.
A40: Interest cover (times) | B40: x | C40: =IF(C38>0,C39/C38,0) -> 13.268293 | D40: =IF(D38>0,D39/D38,0) -> 9.2207297 | E40: =IF(E38>0,E39/E38,0) -> 8.6376628 | F40: =IF(F38>0,F39/F38,0) -> 9.2184836 | G40: =IF(G38>0,G39/G38,0) -> 9.0365449 | H40: =IF(H38>0,H39/H38,0) -> 10.861535 | I40: Before the new project earns a penny. Option 1 has ~3 years of construction with no revenue.
A41: Must the money be repaid? | B41: text | C41: No — shareholders are permanent | D41: Yes — over 25 years | E41: Yes — over 25 years | F41: Yes — in the foreign currency | G41: Yes — at maturity | H41: Yes, the debt part
A43: E. Other risks
A44: Dilutes existing shareholders? | B44: text | C44: Yes — unless they take up their rights | D44: No | E44: No | F44: No | G44: No | H44: Partly
A45: Interest-rate risk? | B45: text | C45: No | D45: Yes — moves with Bank Rate (a rise is expected) | E45: Fixed for 5 years only, then floating | F45: Yes — moves with that currency's rates | G45: No — fixed coupon | H45: Depends on the debt chosen
A46: Currency (FX) risk? | B46: text | C46: No | D46: No | E46: No | F46: Yes — but oil sells in US$, so a $ loan can hedge $ revenue | G46: No (sterling bond) | H46: Depends on the debt chosen | I46: Week 3: borrowing in $ only makes sense if it matches $ you'll earn or owe.
...

Sheet Balance Sheet
A1: Balance Sheet — before and after the rights issue
A2: Financing side of UK Oil's statement of financial position (£M). Week 3 slide 29 method.
A4: Item (£M unless stated) | B4: Before | C4: After: Option 1 | D4: After: Option 2 (80%) | E4: After: Option 2 (100%) | F4: What it means
A6: Equity
A7: £1 Ordinary share capital | B7: =Inputs!$B$6 -> 1000 | C7: =$B$7+'Rights Issue'!C36 -> 1252 | D7: =$B$7+'Rights Issue'!D36 -> 1212 | E7: =$B$7+'Rights Issue'!E36 -> 1264
A8: Share premium (net of issue costs) | B8: 0 | C8: =$B$8+'Rights Issue'!C39 -> 58 | D8: =$B$8+'Rights Issue'!D39 -> 48 | E8: =$B$8+'Rights Issue'!E39 -> 61 | F8: The brief lists no existing share premium, so 'Before' is 0.
A9: Retained profits | B9: =Inputs!$B$11 -> 700 | C9: =$B$9 -> 700 | D9: =$B$9 -> 700 | E9: =$B$9 -> 700 | F9: Unchanged — a rights issue doesn't touch retained profit.
A10: Ordinary shareholders' funds | B10: =B7+B8+B9 -> 1700 | C10: =C7+C8+C9 -> 2010 | D10: =D7+D8+D9 -> 1960 | E10: =E7+E8+E9 -> 2025
A11: £1 6% Preference shares | B11: =Inputs!$B$10 -> 225 | C11: =$B$11 -> 225 | D11: =$B$11 -> 225 | E11: =$B$11 -> 225
A12: Total equity | B12: =B10+B11 -> 1925 | C12: =C10+C11 -> 2235 | D12: =D10+D11 -> 2185 | E12: =E10+E11 -> 2250 | F12: Before = £1,925M per the brief.
A14: Debt
A15: Unsecured 6% Bond 2027 | B15: =Inputs!$B$13 -> 500 | C15: =$B$15 -> 500 | D15: =$B$15 -> 500 | E15: =$B$15 -> 500
A16: Secured loan (floating 7%) | B16: =Inputs!$B$14 -> 200 | C16: =$B$16 -> 200 | D16: =$B$16 -> 200 | E16: =$B$16 -> 200
A17: New debt for any funding NOT raised by the rights issue | B17: 0 | C17: ='Rights Issue'!C7-'Rights Issue'!C9 -> 0 | D17: ='Rights Issue'!D7-'Rights Issue'!D9 -> 0 | E17: ='Rights Issue'!E7-'Rights Issue'!E9 -> 0 | F17: Zero while the Inputs equity share is 100%.
A18: Total debt | B18: =B15+B16+B17 -> 700 | C18: =C15+C16+C17 -> 700 | D18: =D15+D16+D17 -> 700 | E18: =E15+E16+E17 -> 700
A19: Capital employed (equity + debt) | B19: =B12+B18 -> 2625 | C19: =C12+C18 -> 2935 | D19: =D12+D18 -> 2885 | E19: =E12+E18 -> 2950 | F19: Before = £2,625M per the brief.
A20: Check: increase in capital employed = funding need | C20: =IF(ABS((C19-$B$19)-'Rights Issue'!C7)<0.0001,"OK","CHECK") -> OK | D20: =IF(ABS((D19-$B$19)-'Rights Issue'!D7)<0.0001,"OK","CHECK") -> OK | E20: =IF(ABS((E19-$B$19)-'Rights Issue'!E7)<0.0001,"OK","CHECK") -> OK
A22: Per share & gearing
A23: Ordinary shares in issue (M) | B23: =Inputs!$B$8 -> 1000 | C23: ='Rights Issue'!C19 -> 1252 | D23: ='Rights Issue'!D19 -> 1212 | E23: ='Rights Issue'!E19 -> 1264
A24: Book value per ordinary share (£) | B24: =IF(B23>0,B10/B23,0) -> 1.7 | C24: =IF(C23>0,C10/C23,0) -> 1.6054313 | D24: =IF(D23>0,D10/D23,0) -> 1.6171617 | E24: =IF(E23>0,E10/E23,0) -> 1.602057 | F24: Ordinary shareholders' funds ÷ shares. Preference shares excluded — they belong to preference holders.
A25: Change in book value per share vs before (£) | C25: =C24-$B$24 -> -0.09456869 | D25: =D24-$B$24 -> -0.082838284 | E25: =E24-$B$24 -> -0.097943038 | F25: Falls if the issue price is below the existing book value per share.
A26: Gearing — debt ÷ equity | B26: =IF(B12>0,B18/B12,0) -> 0.36363636 | C26: =IF(C12>0,C18/C12,0) -> 0.31319911 | D26: =IF(D12>0,D18/D12,0) -> 0.32036613 | E26: =IF(E12>0,E18/E12,0) -> 0.31111111 | F26: Week 3: lower gearing → lower perceived risk → cheaper future borrowing.
A27: Gearing — debt ÷ (debt + equity) | B27: =IF(B19>0,B18/B19,0) -> 0.26666667 | C27: =IF(C19>0,C18/C19,0) -> 0.23850085 | D27: =IF(D19>0,D18/D19,0) -> 0.24263432 | E27: =IF(E19>0,E18/E19,0) -> 0.23728814
A29: ="Why: the issue price (£"&TEXT(Inputs!$B$18,"0.00")&") is "&IF(Inputs!$B$18<$B$24,"BELOW","ABOVE")&" the current book value per share (£"&TEXT($B$24,"0.00")&"), so book value per share "&IF(Inputs!$B$18<$B$24,"FALLS","RISES")&" after the issue. In the Week 3 example the £2 issue price was above the £1.40 book value, so it rose to £1.50." -> Why: the issue price (£1.25) is BELOW the current book value per share (£1.70), so book value per share FALLS after the issue. In the Week 3 example the £2 issue price was above the £1.40 book value, so it rose to £1.50.

Sheet Dilution
A1: Dilution — what happens to an existing shareholder
A2: Week 3 slides 30–33: take up, sell ('renounce'), or do nothing. £M unless stated.
A4: Item | B4: Unit | C4: Option 1: North Sea | D4: Option 2: Acquire 80% | E4: Option 2: Acquire 100% | F4: What it means
A6: The shareholder
A7: Stake before the issue | B7: % | C7: =Inputs!$B$84 -> 0.05 | D7: =Inputs!$B$84 -> 0.05 | E7: =Inputs!$B$84 -> 0.05 | F7: Set on Inputs (5% = the lecture activity).
A8: Shares held before | B8: M shares | C8: =C7*'Rights Issue'!C16 -> 50 | D8: =D7*'Rights Issue'!D16 -> 50 | E8: =E7*'Rights Issue'!E16 -> 50
A9: Rights entitlement (new shares they may buy) | B9: M shares | C9: =IF('Rights Issue'!C17>0,C8/'Rights Issue'!C17,0) -> 12.6 | D9: =IF('Rights Issue'!D17>0,D8/'Rights Issue'!D17,0) -> 10.6 | E9: =IF('Rights Issue'!E17>0,E8/'Rights Issue'!E17,0) -> 13.2 | F9: Shares held ÷ N.
A10: Cost to take up all the rights | B10: £M | C10: =C9*'Rights Issue'!C12 -> 15.75 | D10: =D9*'Rights Issue'!D12 -> 13.25 | E10: =E9*'Rights Issue'!E12 -> 16.5 | F10: Slide 32: can they afford it?
A12: Ownership after the issue
A13: Stake if rights are TAKEN UP | B13: % | C13: =IF('Rights Issue'!C19>0,(C8+C9)/'Rights Issue'!C19,0) -> 0.05 | D13: =IF('Rights Issue'!D19>0,(D8+D9)/'Rights Issue'!D19,0) -> 0.05 | E13: =IF('Rights Issue'!E19>0,(E8+E9)/'Rights Issue'!E19,0) -> 0.05 | F13: Unchanged — no dilution.
A14: Stake if rights are NOT taken up | B14: % | C14: =IF('Rights Issue'!C19>0,C8/'Rights Issue'!C19,0) -> 0.039936102 | D14: =IF('Rights Issue'!D19>0,D8/'Rights Issue'!D19,0) -> 0.041254125 | E14: =IF('Rights Issue'!E19>0,E8/'Rights Issue'!E19,0) -> 0.039556962 | F14: Slide 33: same shares, bigger pie.
A15: Dilution if not taken up (percentage points) | B15: % | C15: =C14-C7 -> -0.010063898 | D15: =D14-D7 -> -0.0087458746 | E15: =E14-E7 -> -0.010443038
A17: Wealth — market value at TERP (the three choices on slide 30)
A18: Value of holding before (cum-rights) | B18: £M | C18: =C8*'Rights Issue'!C43 -> 175 | D18: =D8*'Rights Issue'!D43 -> 175 | E18: =E8*'Rights Issue'!E43 -> 175
A19: A. Take up — value of all shares after | B19: £M | C19: =(C8+C9)*'Rights Issue'!C46 -> 190.75 | D19: =(D8+D9)*'Rights Issue'!D46 -> 188.25 | E19: =(E8+E9)*'Rights Issue'!E46 -> 191.5
A20: A. Take up — less cash paid in | B20: £M | C20: =-C10 -> -15.75 | D20: =-D10 -> -13.25 | E20: =-E10 -> -16.5
A21: A. Take up — NET WEALTH | B21: £M | C21: =C19+C20 -> 175 | D21: =D19+D20 -> 175 | E21: =E19+E20 -> 175 | F21: Same as before: wealth-neutral, stake protected.
A22: B. Sell rights — value of shares kept | B22: £M | C22: =C8*'Rights Issue'!C46 -> 152.35623 | D22: =D8*'Rights Issue'!D46 -> 155.32178 | E22: =E8*'Rights Issue'!E46 -> 151.50316
A23: B. Sell rights — plus cash from selling the rights | B23: £M | C23: =C9*'Rights Issue'!C48 -> 22.64377 | D23: =D9*'Rights Issue'!D48 -> 19.678218 | E23: =E9*'Rights Issue'!E48 -> 23.496835 | F23: Rights sold at their theoretical nil-paid value.
A24: B. Sell rights — NET WEALTH | B24: £M | C24: =C22+C23 -> 175 | D24: =D22+D23 -> 175 | E24: =E22+E23 -> 175 | F24: Same as before in £, but the stake is diluted.
A25: C. Do nothing & rights lapse unsold — NET WEALTH | B25: £M | C25: =C8*'Rights Issue'!C46 -> 152.35623 | D25: =D8*'Rights Issue'!D46 -> 155.32178 | E25: =E8*'Rights Issue'!E46 -> 151.50316
A26: C. Wealth lost by doing nothing | B26: £M | C26: =C25-C18 -> -22.64377 | D26: =D25-D18 -> -19.678218 | E26: =E25-E18 -> -23.496835 | F26: Slide 30: under Stock Exchange rules lapsed rights are normally sold on your behalf, so in practice C ≈ B.
A28: Book value of the holding (slide 33 method)
A29: Before: shares held × book value per share | B29: £M | C29: =C8*'Balance Sheet'!$B$24 -> 85 | D29: =D8*'Balance Sheet'!$B$24 -> 85 | E29: =E8*'Balance Sheet'!$B$24 -> 85
A30: After — rights taken up | B30: £M | C30: =(C8+C9)*'Balance Sheet'!C24 -> 100.5 | D30: =(D8+D9)*'Balance Sheet'!D24 -> 98 | E30: =(E8+E9)*'Balance Sheet'!E24 -> 101.25
A31: After — rights not taken up | B31: £M | C31: =C8*'Balance Sheet'!C24 -> 80.271565 | D31: =D8*'Balance Sheet'!D24 -> 80.858086 | E31: =E8*'Balance Sheet'!E24 -> 80.102848

Sheet Price Sensitivity
A1: Price Sensitivity — issue price from £1.00 upwards
A2: Pick a scenario in the yellow cell. Prices in blue can be overwritten.
A4: Scenario to test (1 = Option 1, 2 = Option 2 80%, 3 = Option 2 100%) | B4: 3
A5: Scenario | B5: =INDEX('Rights Issue'!$C$4:$E$4,1,$B$4) -> Option 2: Acquire 100%
A6: Net cash needed from the rights issue (£M) | B6: =INDEX('Rights Issue'!$C$9:$E$9,1,$B$4) -> 325
A7: Gross amount to raise incl. fees (£M) | B7: =INDEX('Rights Issue'!$C$11:$E$11,1,$B$4) -> 330
A8: Existing ordinary shares (M) | B8: =Inputs!$B$8 -> 1000
A9: Market price cum-rights (£) | B9: =Inputs!$B$9 -> 3.5
A10: Ordinary shareholders' funds before (£M) | B10: ='Balance Sheet'!$B$10 -> 1700
A11: Value of the right must be over (£) | B11: =Inputs!$B$22 -> 1
A12: Example shareholder's stake before | B12: =Inputs!$B$84 -> 0.05
A14: Issue price (£) | B14: In bank's range? | C14: New shares (M) | D14: N | E14: Rights terms | F14: TERP (£) | G14: Value of right — lecture (£) | H14: Value of nil-paid right (£) | I14: Passes test — lecture? | J14: Passes test — theoretical? | K14: Book value per share after (£) | L14: Stake if rights not taken up
A15: 1 | B15: =IF(AND(A15>=Inputs!$B$19,A15<=Inputs!$B$20),"Yes","No") -> Yes | C15: =IF(A15>0,$B$7/A15,0) -> 330 | D15: =IF(C15>0,$B$8/C15,0) -> 3.030303 | E15: =IF(C15>0,"1 for "&TEXT(D15,"0.00"),"No issue") -> 1 for 3.03 | F15: =IF(C15>0,(D15*$B$9+A15)/(D15+1),$B$9) -> 2.8796992 | G15: =$B$9-A15 -> 2.5 | H15: =F15-A15 -> 1.8796992 | I15: =IF(G15>$B$11,"YES","NO") -> YES | J15: =IF(H15>$B$11,"YES","NO") -> YES | K15: =IF(($B$8+C15)>0,($B$10+$B$6)/($B$8+C15),0) -> 1.5225564 | L15: =IF(($B$8+C15)>0,$B$12*$B$8/($B$8+C15),0) -> 0.037593985
A16: 1.05 | B16: =IF(AND(A16>=Inputs!$B$19,A16<=Inputs!$B$20),"Yes","No") -> Yes | C16: =IF(A16>0,$B$7/A16,0) -> 314.28571 | D16: =IF(C16>0,$B$8/C16,0) -> 3.1818182 | E16: =IF(C16>0,"1 for "&TEXT(D16,"0.00"),"No issue") -> 1 for 3.18 | F16: =IF(C16>0,(D16*$B$9+A16)/(D16+1),$B$9) -> 2.9141304 | G16: =$B$9-A16 -> 2.45 | H16: =F16-A16 -> 1.8641304 | I16: =IF(G16>$B$11,"YES","NO") -> YES | J16: =IF(H16>$B$11,"YES","NO") -> YES | K16: =IF(($B$8+C16)>0,($B$10+$B$6)/($B$8+C16),0) -> 1.5407609 | L16: =IF(($B$8+C16)>0,$B$12*$B$8/($B$8+C16),0) -> 0.038043478
A17: 1.1 | B17: =IF(AND(A17>=Inputs!$B$19,A17<=Inputs!$B$20),"Yes","No") -> Yes | C17: =IF(A17>0,$B$7/A17,0) -> 300 | D17: =IF(C17>0,$B$8/C17,0) -> 3.3333333 | E17: =IF(C17>0,"1 for "&TEXT(D17,"0.00"),"No issue") -> 1 for 3.33 | F17: =IF(C17>0,(D17*$B$9+A17)/(D17+1),$B$9) -> 2.9461538 | G17: =$B$9-A17 -> 2.4 | H17: =F17-A17 -> 1.8461538 | I17: =IF(G17>$B$11,"YES","NO") -> YES | J17: =IF(H17>$B$11,"YES","NO") -> YES | K17: =IF(($B$8+C17)>0,($B$10+$B$6)/($B$8+C17),0) -> 1.5576923 | L17: =IF(($B$8+C17)>0,$B$12*$B$8/($B$8+C17),0) -> 0.038461538
A18: 1.15 | B18: =IF(AND(A18>=Inputs!$B$19,A18<=Inputs!$B$20),"Yes","No") -> Yes | C18: =IF(A18>0,$B$7/A18,0) -> 286.95652 | D18: =IF(C18>0,$B$8/C18,0) -> 3.4848485 | E18: =IF(C18>0,"1 for "&TEXT(D18,"0.00"),"No issue") -> 1 for 3.48 | F18: =IF(C18>0,(D18*$B$9+A18)/(D18+1),$B$9) -> 2.9760135 | G18: =$B$9-A18 -> 2.35 | H18: =F18-A18 -> 1.8260135 | I18: =IF(G18>$B$11,"YES","NO") -> YES | J18: =IF(H18>$B$11,"YES","NO") -> YES | K18: =IF(($B$8+C18)>0,($B$10+$B$6)/($B$8+C18),0) -> 1.5734797 | L18: =IF(($B$8+C18)>0,$B$12*$B$8/($B$8+C18),0) -> 0.038851351
A19: 1.2 | B19: =IF(AND(A19>=Inputs!$B$19,A19<=Inputs!$B$20),"Yes","No") -> Yes | C19: =IF(A19>0,$B$7/A19,0) -> 275 | D19: =IF(C19>0,$B$8/C19,0) -> 3.6363636 | E19: =IF(C19>0,"1 for "&TEXT(D19,"0.00"),"No issue") -> 1 for 3.64 | F19: =IF(C19>0,(D19*$B$9+A19)/(D19+1),$B$9) -> 3.0039216 | G19: =$B$9-A19 -> 2.3 | H19: =F19-A19 -> 1.8039216 | I19: =IF(G19>$B$11,"YES","NO") -> YES | J19: =IF(H19>$B$11,"YES","NO") -> YES | K19: =IF(($B$8+C19)>0,($B$10+$B$6)/($B$8+C19),0) -> 1.5882353 | L19: =IF(($B$8+C19)>0,$B$12*$B$8/($B$8+C19),0) -> 0.039215686
A20: 1.25 | B20: =IF(AND(A20>=Inputs!$B$19,A20<=Inputs!$B$20),"Yes","No") -> Yes | C20: =IF(A20>0,$B$7/A20,0) -> 264 | D20: =IF(C20>0,$B$8/C20,0) -> 3.7878788 | E20: =IF(C20>0,"1 for "&TEXT(D20,"0.00"),"No issue") -> 1 for 3.79 | F20: =IF(C20>0,(D20*$B$9+A20)/(D20+1),$B$9) -> 3.0300633 | G20: =$B$9-A20 -> 2.25 | H20: =F20-A20 -> 1.7800633 | I20: =IF(G20>$B$11,"YES","NO") -> YES | J20: =IF(H20>$B$11,"YES","NO") -> YES | K20: =IF(($B$8+C20)>0,($B$10+$B$6)/($B$8+C20),0) -> 1.602057 | L20: =IF(($B$8+C20)>0,$B$12*$B$8/($B$8+C20),0) -> 0.039556962
A21: 1.5 | B21: =IF(AND(A21>=Inputs!$B$19,A21<=Inputs!$B$20),"Yes","No") -> No | C21: =IF(A21>0,$B$7/A21,0) -> 220 | D21: =IF(C21>0,$B$8/C21,0) -> 4.5454545 | E21: =IF(C21>0,"1 for "&TEXT(D21,"0.00"),"No issue") -> 1 for 4.55 | F21: =IF(C21>0,(D21*$B$9+A21)/(D21+1),$B$9) -> 3.1393443 | G21: =$B$9-A21 -> 2 | H21: =F21-A21 -> 1.6393443 | I21: =IF(G21>$B$11,"YES","NO") -> YES | J21: =IF(H21>$B$11,"YES","NO") -> YES | K21: =IF(($B$8+C21)>0,($B$10+$B$6)/($B$8+C21),0) -> 1.6598361 | L21: =IF(($B$8+C21)>0,$B$12*$B$8/($B$8+C21),0) -> 0.040983607
A22: 2 | B22: =IF(AND(A22>=Inputs!$B$19,A22<=Inputs!$B$20),"Yes","No") -> No | C22: =IF(A22>0,$B$7/A22,0) -> 165 | D22: =IF(C22>0,$B$8/C22,0) -> 6.0606061 | E22: =IF(C22>0,"1 for "&TEXT(D22,"0.00"),"No issue") -> 1 for 6.06 | F22: =IF(C22>0,(D22*$B$9+A22)/(D22+1),$B$9) -> 3.2875536 | G22: =$B$9-A22 -> 1.5 | H22: =F22-A22 -> 1.2875536 | I22: =IF(G22>$B$11,"YES","NO") -> YES | J22: =IF(H22>$B$11,"YES","NO") -> YES | K22: =IF(($B$8+C22)>0,($B$10+$B$6)/($B$8+C22),0) -> 1.7381974 | L22: =IF(($B$8+C22)>0,$B$12*$B$8/($B$8+C22),0) -> 0.042918455
A23: 2.5 | B23: =IF(AND(A23>=Inputs!$B$19,A23<=Inputs!$B$20),"Yes","No") -> No | C23: =IF(A23>0,$B$7/A23,0) -> 132 | D23: =IF(C23>0,$B$8/C23,0) -> 7.5757576 | E23: =IF(C23>0,"1 for "&TEXT(D23,"0.00"),"No issue") -> 1 for 7.58 | F23: =IF(C23>0,(D23*$B$9+A23)/(D23+1),$B$9) -> 3.3833922 | G23: =$B$9-A23 -> 1 | H23: =F23-A23 -> 0.88339223 | I23: =IF(G23>$B$11,"YES","NO") -> NO | J23: =IF(H23>$B$11,"YES","NO") -> NO | K23: =IF(($B$8+C23)>0,($B$10+$B$6)/($B$8+C23),0) -> 1.7888693 | L23: =IF(($B$8+C23)>0,$B$12*$B$8/($B$8+C23),0) -> 0.044169611
A24: 3 | B24: =IF(AND(A24>=Inputs!$B$19,A24<=Inputs!$B$20),"Yes","No") -> No | C24: =IF(A24>0,$B$7/A24,0) -> 110 | D24: =IF(C24>0,$B$8/C24,0) -> 9.0909091 | E24: =IF(C24>0,"1 for "&TEXT(D24,"0.00"),"No issue") -> 1 for 9.09 | F24: =IF(C24>0,(D24*$B$9+A24)/(D24+1),$B$9) -> 3.4504505 | G24: =$B$9-A24 -> 0.5 | H24: =F24-A24 -> 0.45045045 | I24: =IF(G24>$B$11,"YES","NO") -> NO | J24: =IF(H24>$B$11,"YES","NO") -> NO | K24: =IF(($B$8+C24)>0,($B$10+$B$6)/($B$8+C24),0) -> 1.8243243 | L24: =IF(($B$8+C24)>0,$B$12*$B$8/($B$8+C24),0) -> 0.045045045
A26: Rows below the line are OUTSIDE the bank's £1.00–£1.25 range — shown only to find where the 'value of the right over £1.00' test starts to fail.

Sheet Week 3 Example
A1: Week 3 lecture example — proof the method works
A2: Slides 27–34: 500,000 £1 shares, 1-for-5 rights issue at £2, market price £2.50. Same formulas as the UK Oil tabs.
A4: Item | B4: Model | C4: Slide answer | D4: Check | E4: Note
A5: Inputs from the slides
A6: Existing £1 ordinary shares | B6: 500000 | E6: Slide 27.
A7: Nominal value per share (£) | B7: 1 | E7: Slide 28.
A8: Market price per share (£) | B8: 2.5 | E8: Slide 28.
A9: Issue price (£) | B9: 2 | E9: Slide 28.
A10: N — '1 for N' | B10: 5 | E10: 1-for-5.
A11: Non-current assets (£) | B11: 750000 | E11: Slide 27.
A12: Current assets (£) | B12: 100000 | E12: Slide 27.
A13: Current liabilities (£) | B13: 50000 | E13: Slide 27.
A14: Non-current liabilities (£) | B14: 100000 | E14: Slide 27.
A15: Retained profit (£) | B15: 200000 | E15: Slide 27.
A16: Shareholder's stake | B16: 0.05 | E16: Slide 31.
A17: The company
A18: New shares | B18: =B6/B10 -> 100000 | C18: 100000 | D18: =IF(C18="","Formula only",IF(ABS(B18-C18)<0.001,"Matches slide","DIFFERS")) -> Matches slide | E18: Slide 28.
A19: Total shares after | B19: =B6+B18 -> 600000 | C19: 600000 | D19: =IF(C19="","Formula only",IF(ABS(B19-C19)<0.001,"Matches slide","DIFFERS")) -> Matches slide | E19: Slide 28.
A20: Value of the right (market − issue) (£) | B20: =B8-B9 -> 0.5 | C20: 0.5 | D20: =IF(C20="","Formula only",IF(ABS(B20-C20)<0.001,"Matches slide","DIFFERS")) -> Matches slide | E20: Slide 28.
A21: Cash received (£) | B21: =B18*B9 -> 200000 | C21: 200000 | D21: =IF(C21="","Formula only",IF(ABS(B21-C21)<0.001,"Matches slide","DIFFERS")) -> Matches slide | E21: Slide 28.
A22: Increase in share capital (£) | B22: =B18*B7 -> 100000 | C22: 100000 | D22: =IF(C22="","Formula only",IF(ABS(B22-C22)<0.001,"Matches slide","DIFFERS")) -> Matches slide | E22: Slide 29.
A23: Share premium (£) | B23: =B18*(B9-B7) -> 100000 | C23: 100000 | D23: =IF(C23="","Formula only",IF(ABS(B23-C23)<0.001,"Matches slide","DIFFERS")) -> Matches slide | E23: Slide 28.
A24: Net assets before (£) | B24: =B11+B12-B13-B14 -> 700000 | C24: 700000 | D24: =IF(C24="","Formula only",IF(ABS(B24-C24)<0.001,"Matches slide","DIFFERS")) -> Matches slide | E24: Slide 27.
A25: Equity before: share capital + retained profit (£) | B25: =B6*B7+B15 -> 700000 | C25: 700000 | D25: =IF(C25="","Formula only",IF(ABS(B25-C25)<0.001,"Matches slide","DIFFERS")) -> Matches slide | E25: Must equal net assets.
A26: Book value per share before (£) | B26: =B25/B6 -> 1.4 | C26: 1.4 | D26: =IF(C26="","Formula only",IF(ABS(B26-C26)<0.001,"Matches slide","DIFFERS")) -> Matches slide | E26: Slide 27.
A27: Net assets after: before + cash (£) | B27: =B24+B21 -> 900000 | C27: 900000 | D27: =IF(C27="","Formula only",IF(ABS(B27-C27)<0.001,"Matches slide","DIFFERS")) -> Matches slide | E27: Slide 29.
A28: Equity after: share capital + premium + retained profit (£) | B28: =B6*B7+B22+B23+B15 -> 900000 | C28: 900000 | D28: =IF(C28="","Formula only",IF(ABS(B28-C28)<0.001,"Matches slide","DIFFERS")) -> Matches slide | E28: Slide 29.
A29: Book value per share after (£) | B29: =B28/B19 -> 1.5 | C29: 1.5 | D29: =IF(C29="","Formula only",IF(ABS(B29-C29)<0.001,"Matches slide","DIFFERS")) -> Matches slide | E29: Slide 29.
A30: TERP: (N × cum-rights price + issue price) ÷ (N + 1) (£) | B30: =(B10*B8+B9)/(B10+1) -> 2.4166667 | D30: =IF(C30="","Formula only",IF(ABS(B30-C30)<0.001,"Matches slide","DIFFERS")) -> Formula only | E30: Slide 34 gives only the formula.
A31: The shareholder
A32: Shares held | B32: =B6*B16 -> 25000 | C32: 25000 | D32: =IF(C32="","Formula only",IF(ABS(B32-C32)<0.001,"Matches slide","DIFFERS")) -> Matches slide | E32: Slide 31.
A33: Rights entitlement (new shares) | B33: =B32/B10 -> 5000 | C33: 5000 | D33: =IF(C33="","Formula only",IF(ABS(B33-C33)<0.001,"Matches slide","DIFFERS")) -> Matches slide | E33: Slide 31.
A34: Cost to take up (£) | B34: =B33*B9 -> 10000 | C34: 10000 | D34: =IF(C34="","Formula only",IF(ABS(B34-C34)<0.001,"Matches slide","DIFFERS")) -> Matches slide | E34: Slide 32.
A35: Book value of holding before (£) | B35: =B32*B26 -> 35000 | C35: 35000 | D35: =IF(C35="","Formula only",IF(ABS(B35-C35)<0.001,"Matches slide","DIFFERS")) -> Matches slide | E35: Slide 33.
A36: Book value of holding after, rights taken up (£) | B36: =(B32+B33)*B29 -> 45000 | C36: 45000 | D36: =IF(C36="","Formula only",IF(ABS(B36-C36)<0.001,"Matches slide","DIFFERS")) -> Matches slide | E36: Slide 33.
A37: Stake if rights not taken up | B37: =B32/B19 -> 0.041666667 | C37: 0.0416 | D37: =IF(C37="","Formula only",IF(ABS(B37-C37)<0.001,"Matches slide","DIFFERS")) -> Matches slide | E37: Slide 33 shows 4.16% (it truncates 4.1667%).
